Workbook

Sheet ETUDE
A1: =IFERROR("FICHE D'ANALYSE BRVM — "&PROFIL!B3&" ("&PROFIL!B4&") | "&PROFIL!B5&" | "&TEXT(PROFIL!B6,"dd/mm/yyyy"),"FICHE D'ANALYSE BRVM — [Completer onglet PROFIL]") -> 0
A2: =IFERROR("Nom : "&PROFIL!B3&" | Ticker : "&PROFIL!B4&" | Secteur : "&PROFIL!B5&" | Date analyse : "&TEXT(PROFIL!B6,"dd/mm/yyyy"),"Completer le PROFIL : nom, ticker, secteur, date") -> 0
A4: A — ANALYSE FONDAMENTALE
A6: A1 — CHIFFRE D'AFFAIRES ou PRODUIT NET BANCAIRE (en millions FCFA)
B7: N-4 | C7: N-3 | D7: N-2 | E7: N-1 | F7: N (dernier) | G7: Croissance N/N-4 % | H7: TCAM 4 ans %
A8: CA / PNB | G8: =IF(B8=0,"",((F8-B8)/B8)*100) -> 0 | H8: =IF(OR(B8=0,F8=0),"",(F8/B8)^(1/4)-1) -> 0
A10: A2 — RESULTAT NET (en millions FCFA)
B11: N-4 | C11: N-3 | D11: N-2 | E11: N-1 | F11: N (dernier) | G11: Croissance N/N-4 % | H11: TCAM 4 ans %
A12: Resultat Net | G12: =IF(B12=0,"",((F12-B12)/ABS(B12))*100) -> 0 | H12: =IF(OR(B12=0,F12/B12<0),"N/A",(F12/B12)^(1/4)-1) -> 0
A14: A3 — MARGE NETTE (RN / CA x 100) — 5 dernieres annees
A15: Annee | B15: RN (M FCFA) | C15: CA/PNB (M FCFA) | D15: Marge % | E15: Interpretation | F15: Seuil | G15: Moyenne 5 ans %
A16: N-4 | B16: =B12 -> 0 | C16: =B8 -> 0 | D16: =IFERROR(B16/C16*100,"") -> 0 | E16: =IFERROR(IF(D16>=10,"Tres rentable",IF(D16>=5,"Rentable",IF(D16>=2,"Faiblement rentable","Tres faible"))),"-") -> 0 | F16: > 5% = bon | G16: =IFERROR(AVERAGE(D16:D20),"") -> 0
A17: N-3 | B17: =C12 -> 0 | C17: =C8 -> 0 | D17: =IFERROR(B17/C17*100,"") -> 0 | E17: =IFERROR(IF(D17>=10,"Tres rentable",IF(D17>=5,"Rentable",IF(D17>=2,"Faiblement rentable","Tres faible"))),"-") -> 0
A18: N-2 | B18: =D12 -> 0 | C18: =D8 -> 0 | D18: =IFERROR(B18/C18*100,"") -> 0 | E18: =IFERROR(IF(D18>=10,"Tres rentable",IF(D18>=5,"Rentable",IF(D18>=2,"Faiblement rentable","Tres faible"))),"-") -> 0
A19: N-1 | B19: =E12 -> 0 | C19: =E8 -> 0 | D19: =IFERROR(B19/C19*100,"") -> 0 | E19: =IFERROR(IF(D19>=10,"Tres rentable",IF(D19>=5,"Rentable",IF(D19>=2,"Faiblement rentable","Tres faible"))),"-") -> 0
A20: N | B20: =F12 -> 0 | C20: =F8 -> 0 | D20: =IFERROR(B20/C20*100,"") -> 0 | E20: =IFERROR(IF(D20>=10,"Tres rentable",IF(D20>=5,"Rentable",IF(D20>=2,"Faiblement rentable","Tres faible"))),"-") -> 0
A22: A4 — INDICATEURS DE VALORISATION
A23: Indicateur [formule] | B23: Valeur calculee | C23: Zone reference | D23: Signal
A24: Prix actuel de l'action (FCFA) | C24: <-- Saisir le prix actuel
A25: BNPA — Benefice Net Par Action (FCFA) | C25: <-- RN / Nb titres (rapport annuel)
A26: Capitaux Propres (FCFA) | C26: <-- Bilan comptable
A27: Capitalisation boursiere (FCFA) | C27: <-- Prix x Nb titres
A28: Nombre de titres en circulation | B28: =IFERROR(PROFIL!B17,"") -> 0 | C28: <-- Auto depuis PROFIL onglet (Capital & Actionnariat)
A30: PER — Price Earning Ratio [= Prix / BNPA] | B30: =IFERROR(B24/B25,"") -> 0 | C30: Zone : 9-15 | D30: =IFERROR(IF(B30>15,"Surevalue",IF(B30<9,"Sous-evalue","Zone normale (9-15)")),"-") -> 0
A31: VMC — Valeur Mathematique Comptable [= Capitaux Propres / Nb titres] | B31: =IFERROR(B26/B28,"") -> 0 | C31: Prix < VMC = bon | D31: =IFERROR(IF(B24>B31,"Action surevaluee vs VMC","Action sous-evaluee vs VMC"),"-") -> 0
A32: PBR — Price to Book Ratio [= Capitalisation / Capitaux Propres] | B32: =IFERROR(B27/B26,"") -> 0 | C32: < 1 = decote | D32: =IFERROR(IF(B32<1,"Decote comptable",IF(B32<2,"Normal","Prime elevee")),"-") -> 0
A33: ROE — Return on Equity (%) [= RN / Capitaux Propres x 100] | B33: =IFERROR(F12*1000000/B26*100,"") -> 0 | C33: > 10% = bon | D33: =IFERROR(IF(B33>=15,"Excellent",IF(B33>=10,"Bon",IF(B33>=5,"Moyen","Faible"))),"-") -> 0
A34: RVC — PER x PBR (Lynch) [= PER x PBR] | B34: =IFERROR(B30*B32,"") -> 0 | C34: < 22 = decote | D34: =IFERROR(IF(B34<22,"Decote globale (achat possible)","Surevaluation"),"-") -> 0
A36: A5 — DIVIDENDES & TAUX DE DISTRIBUTION
A37: Annee | B37: Dividende NET recu (FCFA) | C37: BNPA (FCFA) | D37: Taux distrib. % | E37: Rendement % | F37: Progression %
A38: Dividende NET = montant effectivement recu apres prelevement 15% a la source. Taux distribution = (Div NET / 0,85) / BNPA x 100 (reconstitution du brut)
A39: N-4 | D39: =IFERROR((B39/0.85)/C39*100,"") -> 0 | E39: =IFERROR(B39/B24*100,"") -> 0
A40: N-3 | D40: =IFERROR((B40/0.85)/C40*100,"") -> 0 | E40: =IFERROR(B40/B24*100,"") -> 0 | F40: =IFERROR((B40-B39)/ABS(B39)*100,"") -> 0
A41: N-2 | D41: =IFERROR((B41/0.85)/C41*100,"") -> 0 | E41: =IFERROR(B41/B24*100,"") -> 0 | F41: =IFERROR((B41-B40)/ABS(B40)*100,"") -> 0
A42: N-1 | D42: =IFERROR((B42/0.85)/C42*100,"") -> 0 | E42: =IFERROR(B42/B24*100,"") -> 0 | F42: =IFERROR((B42-B41)/ABS(B41)*100,"") -> 0
A43: N | D43: =IFERROR((B43/0.85)/C43*100,"") -> 0 | E43: =IFERROR(B43/B24*100,"") -> 0 | F43: =IFERROR((B43-B42)/ABS(B42)*100,"") -> 0
A44: TOTAL / MOYENNE | B44: =SUM(B39:B43) -> 0 | D44: =IFERROR(AVERAGE(D39:D43),"") -> 0 | E44: =IFERROR(AVERAGE(E39:E43),"") -> 0
A45: A6 — FONDS PROPRES (FCFA)
A46: Composante | B46: Annee N-1 | C46: Annee N | D46: Variation %
A47: Capital souscrit | D47: =IFERROR((C47-B47)/ABS(B47)*100,"") -> 0
...

Sheet SYNTHESE
A1: TABLEAU DE BORD — SYNTHESE DE L'ANALYSE
A2: =IFERROR(PROFIL!B3&" ("&PROFIL!B4&") | "&PROFIL!B5&" | Prix : "&TEXT(ETUDE!B24,"#,##0")&" FCFA | Date : "&TEXT(PROFIL!B6,"dd/mm/yyyy"),"Completer le PROFIL") -> 0
A4: SCORECARD FONDAMENTALE
A5: Critere | B5: Valeur (auto depuis ETUDE) | C5: Zone normale | D5: Signal (auto) | E5: Score (0-3)
A6: Croissance CA (N/N-4 %) | B6: =IFERROR(ETUDE!G8,"") -> 0 | C6: > 10% | D6: =IFERROR(IF(ETUDE!G8>=10,"Bon (>=10%)",IF(ETUDE!G8>=0,"Faible (<10%)","Negatif")),"-") -> 0
A7: Croissance RN (N/N-4 %) | B7: =IFERROR(ETUDE!G12,"") -> 0 | C7: > 10% | D7: =IFERROR(IF(ETUDE!G12>=10,"Bon (>=10%)",IF(ETUDE!G12>=0,"Faible (<10%)","Negatif")),"-") -> 0
A8: Marge nette moyenne (%) | B8: =IFERROR(ETUDE!G16,"") -> 0 | C8: > 5% | D8: =IFERROR(IF(ETUDE!G16>=10,"Tres rentable",IF(ETUDE!G16>=5,"Rentable",IF(ETUDE!G16>=2,"Faiblement rentable","Faible"))),"-") -> 0
A9: PER | B9: =IFERROR(ETUDE!B30,"") -> 0 | C9: 9 - 15 | D9: =IFERROR(ETUDE!D30,"-") -> 0
A10: PBR | B10: =IFERROR(ETUDE!B32,"") -> 0 | C10: < 1 ideal | D10: =IFERROR(ETUDE!D32,"-") -> 0
A11: ROE (%) | B11: =IFERROR(ETUDE!B33,"") -> 0 | C11: > 10% | D11: =IFERROR(ETUDE!D33,"-") -> 0
A12: Rendement dividende (%) | B12: =IFERROR(AVERAGE(ETUDE!E39:ETUDE!E43),"") -> 0 | C12: > 3% | D12: =IFERROR(IF(AVERAGE(ETUDE!E39:ETUDE!E43)>=3,"Bon (>=3%)","Faible (<3%)"),"-") -> 0
A13: RVC (PER x PBR) | B13: =IFERROR(ETUDE!B34,"") -> 0 | C13: < 22 | D13: =IFERROR(ETUDE!D34,"-") -> 0
A14: SCORE FONDAMENTAL TOTAL (/24) | E14: =SUM(E6:E13) -> 0
A16: SCORECARD TECHNIQUE
A17: Critere | B17: Signal observe | C17: Zone | D17: Interpretation | E17: Score
A18: MM20+Bollinger+MACD+RSI+Volume (score B1) | B18: =IFERROR(ETUDE!D91,"") -> 0 | C18: -5 a +5 | D18: =IFERROR(ETUDE!E91,"-") -> 0
A19: Prix Medians PM1 et PM2 (B2) | B19: =IFERROR(ETUDE!E95,"") -> 0 | C19: < PM = survente | D19: =IFERROR(ETUDE!E96,"-") -> 0
A20: PER actualise (B3) | B20: =IFERROR(ETUDE!B104,"") -> 0 | C20: 9-15 = normal | D20: =IFERROR(ETUDE!D104,"-") -> 0
A21: PCD / Gordon-Shapiro (B4/B5) | B21: =IFERROR(ETUDE!B116,"") -> 0 | C21: < PCD = survente | D21: =IFERROR(ETUDE!B125,"-") -> 0
A22: Risk/Reward (B6) | B22: =IFERROR(ETUDE!B135,"") -> 0 | C22: >= 2 = bon | D22: =IFERROR(ETUDE!D135,"-") -> 0
A23: SCORE TECHNIQUE TOTAL (/15) | E23: =SUM(E18:E22) -> 0
A25: VERDICT GLOBAL
A26: Composante | B26: Score | C26: Max | D26: % atteint | E26: Appreciation
A27: Score Fondamental | B27: =E14 -> 0 | C27: 24 | D27: =IFERROR(E14/24*100,"") -> 0 | E27: =IFERROR(IF(E14/24>=0.7,"Solide",IF(E14/24>=0.5,"Moyen","Faible")),"-") -> 0
A28: Score Technique | B28: =E23 -> 0 | C28: 15 | D28: =IFERROR(E23/15*100,"") -> 0 | E28: =IFERROR(IF(E23/15>=0.7,"Solide",IF(E23/15>=0.5,"Moyen","Faible")),"-") -> 0
A29: SCORE TOTAL | B29: =IFERROR(E14+E23,"") -> 0 | C29: 39 | D29: =IFERROR(B29/39*100,"") -> 0 | E29: =IFERROR(IF(B29/39>=0.7,"ACHETER",IF(B29/39>=0.5,"SURVEILLER","EVITER")),"-") -> 0
A31: C — SIGNAL CONTRARIAN BRVM (depuis ETUDE C4)
A32: Score /10 | B32: Verdict | C32: PER Normalise | D32: PER vs Sectoriel | E32: Decote VMC
A33: =IFERROR(ETUDE!D178,"") -> 0 | B33: =IFERROR(ETUDE!E179,"-") -> 0 | C33: =IFERROR(ETUDE!D153,"") -> 0 | D33: =IFERROR(ETUDE!D161,"") -> 0 | E33: =IFERROR(IF(ETUDE!B24<ETUDE!B31,"Prix < VMC","Prix > VMC"),"-") -> 0
A35: RECOMMANDATION FINALE (texte libre)

Sheet PROFIL
A1: PROFIL DE LA SOCIETE
A2: DONNEES CLES — liees automatiquement a ETUDE et SYNTHESE
A3: Nom de la societe | D3: PROFIL!B3 -> titre de ETUDE et SYNTHESE
A4: Ticker BRVM | D4: ex: BIDC, ETIT, SNTS, ONTBF...
A5: Secteur d activite | D5: Banque | Assurance | Industrie | Distribution | Telecom | Autre
A6: Date d analyse | D6: ex: 14/05/2026 (texte libre)
A8: IDENTIFICATION COMPLETE
A9: Nom complet | B9: =B3 -> 0 | C9: <-- Auto depuis cellules cles ci-dessus
A10: Ticker BRVM | B10: =B4 -> 0 | C10: <-- Auto depuis cellules cles ci-dessus
A11: Secteur d'activite | B11: =B5 -> 0 | C11: <-- Auto depuis cellules cles ci-dessus
A12: Pays d'origine
A13: Date d'introduction en bourse
A15: CAPITAL & ACTIONNARIAT
A16: Capital social (FCFA)
A17: Nombre de titres
A18: Flottant (%)
A19: Principaux actionnaires
A21: LIQUIDITE DU TITRE (critique sur BRVM)
A22: Volume moyen journalier (titres) | B22: <-- Source : BRVM.org
A23: Volume moyen journalier (FCFA)
A24: Frequence de cotation (%) | B24: <-- % seances avec transaction
A25: Appreciation liquidite | B25: <-- Forte / Moyenne / Faible
A27: NOTATION & CONFORMITE
A28: Agence de notation
A29: Note court terme
A30: Note long terme
A31: Dividende verse regulierement ? | B31: <-- Oui / Non
A33: SOURCES D'INFORMATION
A34: Rapport annuel | B34: <-- Lien ou date
A35: Site de la societe
A36: Profil RichBourse | B36: <-- richbourse.com
A37: Profil BRVM | B37: <-- brvm.org

Sheet FORMULE
A1: REFERENTIEL DES FORMULES & INDICATEURS BRVM
A2: Indicateur | B2: Expression mathematique | C2: Unite | D2: Interpretation / Seuils BRVM
A3: ANALYSE FONDAMENTALE
A4: Croissance N/N-4 | B4: (N - N-4) / |N-4| x 100 | C4: % | D4: Positif = croissance. Negatif = contraction. Seuil : > 10%/an = excellent
A5: TCAM (CAGR) | B5: (N / N-4)^(1/4) - 1 | C5: % | D5: Taux de Croissance Annuel Moyen sur 4 ans
A6: Marge Nette | B6: RN / CA x 100 | C6: % | D6: < 2% = faible | 2-5% = moyen | > 5% = bon | > 10% = tres bon
A7: PER | B7: Prix / BNPA | C7: fois | D7: Zone normale BRVM : 9-15. > 15 = surevalue, < 9 = sous-evalue
A8: VMC | B8: Capitaux Propres / Nb titres | C8: FCFA | D8: Prix < VMC = action decotee (achat potentiellement interessant)
A9: PBR | B9: Capitalisation / Capitaux Propres | C9: fois | D9: < 1 = decote sur actif net | > 2 = prime significative
A10: ROE | B10: RN / Capitaux Propres x 100 | C10: % | D10: < 5% = faible | 5-10% = moyen | 10-15% = bon | > 15% = excellent
A11: RVC (Lynch) | B11: PER x PBR | D11: < 22 = decote globale. Indicateur de sous-valorisation composite
A12: Taux de distribution | B12: DVD / (BNPA x 0.85) x 100 | C12: % | D12: 0.85 = prefcompte 15% BRVM. > 100% = distribution > benefice
A13: Rendement dividende | B13: Dividende / Prix x 100 | C13: % | D13: < 2% = faible | 2-5% = bon | > 5% = tres attractif
A14: ANALYSE TECHNIQUE
A15: Prix Median (PM) | B15: (Plus Haut + Plus Bas) / 2 | C15: FCFA | D15: Prix < PM = zone survente. Calculer sur 1 an ET 2 ans SEPAREMENT
A16: RSI | B16: Calcule sur graphique | D16: < 30 = survente | 30-70 = neutre | > 70 = surachat
A17: MACD | B17: Calcule sur graphique | D17: MACD > Signal = signal haussier
A18: PER actualise | B18: Prix / (BNPA x (1 + evol RN%)) | C18: fois | D18: Integre la derniere variation du RN. Plus precis que le PER historique
A19: PCD | B19: 100 x DVD_prev / Rendement_secteur% | C19: FCFA | D19: Rendement sectoriel BRVM : 5-8%. Applicable seulement si dividende > 0
A20: Gordon-Shapiro | B20: P0 = D1 / (r - g) | C20: FCFA | D20: D1 = dividende attendu | r = taux exige | g = croissance dividendes
A21: GESTION DU RISQUE
A22: Stop-Loss (10%) | B22: Prix d'achat x 0.90 | C22: FCFA | D22: Limite de perte acceptable. Adapter selon profil de risque
A23: Risk/Reward | B23: Gain potentiel / Perte potentielle | C23: ratio | D23: < 1 = mauvais | 1-2 = acceptable | >= 2 = bon
A24: CMP (frais achat) | B24: Prix x 1.014 | C24: FCFA | D24: Integre la commission d'achat BRVM de 1.4%
A25: Taxe de cession | B25: Prix x 1.4% | C25: FCFA | D25: Taxe applicable a la vente sur BRVM
